Traceback (most recent call last):
  File "/usr/local/lib64/python3.6/site-packages/django/core/handlers/exception.py", line 34, in inner
    response = get_response(request)
  File "/usr/local/lib64/python3.6/site-packages/django/core/handlers/base.py", line 100, in _get_response
    resolver_match = resolver.resolve(request.path_info)
  File "/usr/local/lib64/python3.6/site-packages/django/urls/resolvers.py", line 544, in resolve
    for pattern in self.url_patterns:
  File "/usr/local/lib64/python3.6/site-packages/django/utils/functional.py", line 48, in __get__
    res = instance.__dict__[self.name] = self.func(instance)
  File "/usr/local/lib64/python3.6/site-packages/django/urls/resolvers.py", line 588, in url_patterns
    patterns = getattr(self.urlconf_module, "urlpatterns", self.urlconf_module)
  File "/usr/local/lib64/python3.6/site-packages/django/utils/functional.py", line 48, in __get__
    res = instance.__dict__[self.name] = self.func(instance)
  File "/usr/local/lib64/python3.6/site-packages/django/urls/resolvers.py", line 581, in urlconf_module
    return import_module(self.urlconf_name)
  File "/usr/lib64/python3.6/importlib/__init__.py", line 126, in import_module
    return _bootstrap._gcd_import(name[level:], package, level)
  File "<frozen importlib._bootstrap>", line 994, in _gcd_import
  File "<frozen importlib._bootstrap>", line 971, in _find_and_load
  File "<frozen importlib._bootstrap>", line 955, in _find_and_load_unlocked
  File "<frozen importlib._bootstrap>", line 665, in _load_unlocked
  File "<frozen importlib._bootstrap_external>", line 678, in exec_module
  File "<frozen importlib._bootstrap>", line 219, in _call_with_frames_removed
  File "./XiaoChengxu/urls.py", line 18, in <module>
    from django.views.generic.base import RediectView
ImportError: cannot import name 'RediectView'

During handling of the above exception, another exception occurred:

Traceback (most recent call last):
  File "/usr/local/lib64/python3.6/site-packages/django/core/handlers/exception.py", line 34, in inner
    response = get_response(request)
  File "/usr/local/lib64/python3.6/site-packages/django/utils/deprecation.py", line 94, in __call__
    response = response or self.get_response(request)
  File "/usr/local/lib64/python3.6/site-packages/django/core/handlers/exception.py", line 36, in inner
    response = response_for_exception(request, exc)
  File "/usr/local/lib64/python3.6/site-packages/django/core/handlers/exception.py", line 90, in response_for_exception
    response = handle_uncaught_exception(request, get_resolver(get_urlconf()), sys.exc_info())
  File "/usr/local/lib64/python3.6/site-packages/django/core/handlers/exception.py", line 128, in handle_uncaught_exception
    callback, param_dict = resolver.resolve_error_handler(500)
  File "/usr/local/lib64/python3.6/site-packages/django/urls/resolvers.py", line 601, in resolve_error_handler
    callback = getattr(self.urlconf_module, 'handler%s' % view_type, None)
  File "/usr/local/lib64/python3.6/site-packages/django/utils/functional.py", line 48, in __get__
    res = instance.__dict__[self.name] = self.func(instance)
  File "/usr/local/lib64/python3.6/site-packages/django/urls/resolvers.py", line 581, in urlconf_module
    return import_module(self.urlconf_name)
  File "/usr/lib64/python3.6/importlib/__init__.py", line 126, in import_module
    return _bootstrap._gcd_import(name[level:], package, level)
  File "<frozen importlib._bootstrap>", line 994, in _gcd_import
  File "<frozen importlib._bootstrap>", line 971, in _find_and_load
  File "<frozen importlib._bootstrap>", line 955, in _find_and_load_unlocked
  File "<frozen importlib._bootstrap>", line 665, in _load_unlocked
  File "<frozen importlib._bootstrap_external>", line 678, in exec_module
  File "<frozen importlib._bootstrap>", line 219, in _call_with_frames_removed
  File "./XiaoChengxu/urls.py", line 18, in <module>
    from django.views.generic.base import RediectView
ImportError: cannot import name 'RediectView'

During handling of the above exception, another exception occurred:

Traceback (most recent call last):
  File "/usr/local/lib64/python3.6/site-packages/django/core/handlers/exception.py", line 34, in inner
    response = get_response(request)
  File "/usr/local/lib64/python3.6/site-packages/django/utils/deprecation.py", line 94, in __call__
    response = response or self.get_response(request)
  File "/usr/local/lib64/python3.6/site-packages/django/core/handlers/exception.py", line 36, in inner
    response = response_for_exception(request, exc)
  File "/usr/local/lib64/python3.6/site-packages/django/core/handlers/exception.py", line 90, in response_for_exception
    response = handle_uncaught_exception(request, get_resolver(get_urlconf()), sys.exc_info())
  File "/usr/local/lib64/python3.6/site-packages/django/core/handlers/exception.py", line 128, in handle_uncaught_exception
    callback, param_dict = resolver.resolve_error_handler(500)
  File "/usr/local/lib64/python3.6/site-packages/django/urls/resolvers.py", line 601, in resolve_error_handler
    callback = getattr(self.urlconf_module, 'handler%s' % view_type, None)
  File "/usr/local/lib64/python3.6/site-packages/django/utils/functional.py", line 48, in __get__
    res = instance.__dict__[self.name] = self.func(instance)
  File "/usr/local/lib64/python3.6/site-packages/django/urls/resolvers.py", line 581, in urlconf_module
    return import_module(self.urlconf_name)
  File "/usr/lib64/python3.6/importlib/__init__.py", line 126, in import_module
    return _bootstrap._gcd_import(name[level:], package, level)
  File "<frozen importlib._bootstrap>", line 994, in _gcd_import
  File "<frozen importlib._bootstrap>", line 971, in _find_and_load
  File "<frozen importlib._bootstrap>", line 955, in _find_and_load_unlocked
  File "<frozen importlib._bootstrap>", line 665, in _load_unlocked
  File "<frozen importlib._bootstrap_external>", line 678, in exec_module
  File "<frozen importlib._bootstrap>", line 219, in _call_with_frames_removed
  File "./XiaoChengxu/urls.py", line 18, in <module>
    from django.views.generic.base import RediectView
ImportError: cannot import name 'RediectView'

During handling of the above exception, another exception occurred:

Traceback (most recent call last):
  File "/usr/local/lib64/python3.6/site-packages/django/core/handlers/exception.py", line 34, in inner
    response = get_response(request)
  File "/usr/local/lib64/python3.6/site-packages/django/utils/deprecation.py", line 94, in __call__
    response = response or self.get_response(request)
  File "/usr/local/lib64/python3.6/site-packages/django/core/handlers/exception.py", line 36, in inner
    response = response_for_exception(request, exc)
  File "/usr/local/lib64/python3.6/site-packages/django/core/handlers/exception.py", line 90, in response_for_exception
    response = handle_uncaught_exception(request, get_resolver(get_urlconf()), sys.exc_info())
  File "/usr/local/lib64/python3.6/site-packages/django/core/handlers/exception.py", line 128, in handle_uncaught_exception
    callback, param_dict = resolver.resolve_error_handler(500)
  File "/usr/local/lib64/python3.6/site-packages/django/urls/resolvers.py", line 601, in resolve_error_handler
    callback = getattr(self.urlconf_module, 'handler%s' % view_type, None)
  File "/usr/local/lib64/python3.6/site-packages/django/utils/functional.py", line 48, in __get__
    res = instance.__dict__[self.name] = self.func(instance)
  File "/usr/local/lib64/python3.6/site-packages/django/urls/resolvers.py", line 581, in urlconf_module
    return import_module(self.urlconf_name)
  File "/usr/lib64/python3.6/importlib/__init__.py", line 126, in import_module
    return _bootstrap._gcd_import(name[level:], package, level)
  File "<frozen importlib._bootstrap>", line 994, in _gcd_import
  File "<frozen importlib._bootstrap>", line 971, in _find_and_load
  File "<frozen importlib._bootstrap>", line 955, in _find_and_load_unlocked
  File "<frozen importlib._bootstrap>", line 665, in _load_unlocked
  File "<frozen importlib._bootstrap_external>", line 678, in exec_module
  File "<frozen importlib._bootstrap>", line 219, in _call_with_frames_removed
  File "./XiaoChengxu/urls.py", line 18, in <module>
    from django.views.generic.base import RediectView
ImportError: cannot import name 'RediectView'

During handling of the above exception, another exception occurred:

Traceback (most recent call last):
  File "/usr/local/lib64/python3.6/site-packages/django/core/handlers/exception.py", line 34, in inner
    response = get_response(request)
  File "/usr/local/lib64/python3.6/site-packages/django/utils/deprecation.py", line 94, in __call__
    response = response or self.get_response(request)
  File "/usr/local/lib64/python3.6/site-packages/django/core/handlers/exception.py", line 36, in inner
    response = response_for_exception(request, exc)
  File "/usr/local/lib64/python3.6/site-packages/django/core/handlers/exception.py", line 90, in response_for_exception
    response = handle_uncaught_exception(request, get_resolver(get_urlconf()), sys.exc_info())
  File "/usr/local/lib64/python3.6/site-packages/django/core/handlers/exception.py", line 128, in handle_uncaught_exception
    callback, param_dict = resolver.resolve_error_handler(500)
  File "/usr/local/lib64/python3.6/site-packages/django/urls/resolvers.py", line 601, in resolve_error_handler
    callback = getattr(self.urlconf_module, 'handler%s' % view_type, None)
  File "/usr/local/lib64/python3.6/site-packages/django/utils/functional.py", line 48, in __get__
    res = instance.__dict__[self.name] = self.func(instance)
  File "/usr/local/lib64/python3.6/site-packages/django/urls/resolvers.py", line 581, in urlconf_module
    return import_module(self.urlconf_name)
  File "/usr/lib64/python3.6/importlib/__init__.py", line 126, in import_module
    return _bootstrap._gcd_import(name[level:], package, level)
  File "<frozen importlib._bootstrap>", line 994, in _gcd_import
  File "<frozen importlib._bootstrap>", line 971, in _find_and_load
  File "<frozen importlib._bootstrap>", line 955, in _find_and_load_unlocked
  File "<frozen importlib._bootstrap>", line 665, in _load_unlocked
  File "<frozen importlib._bootstrap_external>", line 678, in exec_module
  File "<frozen importlib._bootstrap>", line 219, in _call_with_frames_removed
  File "./XiaoChengxu/urls.py", line 18, in <module>
    from django.views.generic.base import RediectView
ImportError: cannot import name 'RediectView'

During handling of the above exception, another exception occurred:

Traceback (most recent call last):
  File "/usr/local/lib64/python3.6/site-packages/django/core/handlers/exception.py", line 34, in inner
    response = get_response(request)
  File "/usr/local/lib64/python3.6/site-packages/django/utils/deprecation.py", line 94, in __call__
    response = response or self.get_response(request)
  File "/usr/local/lib64/python3.6/site-packages/django/core/handlers/exception.py", line 36, in inner
    response = response_for_exception(request, exc)
  File "/usr/local/lib64/python3.6/site-packages/django/core/handlers/exception.py", line 90, in response_for_exception
    response = handle_uncaught_exception(request, get_resolver(get_urlconf()), sys.exc_info())
  File "/usr/local/lib64/python3.6/site-packages/django/core/handlers/exception.py", line 128, in handle_uncaught_exception
    callback, param_dict = resolver.resolve_error_handler(500)
  File "/usr/local/lib64/python3.6/site-packages/django/urls/resolvers.py", line 601, in resolve_error_handler
    callback = getattr(self.urlconf_module, 'handler%s' % view_type, None)
  File "/usr/local/lib64/python3.6/site-packages/django/utils/functional.py", line 48, in __get__
    res = instance.__dict__[self.name] = self.func(instance)
  File "/usr/local/lib64/python3.6/site-packages/django/urls/resolvers.py", line 581, in urlconf_module
    return import_module(self.urlconf_name)
  File "/usr/lib64/python3.6/importlib/__init__.py", line 126, in import_module
    return _bootstrap._gcd_import(name[level:], package, level)
  File "<frozen importlib._bootstrap>", line 994, in _gcd_import
  File "<frozen importlib._bootstrap>", line 971, in _find_and_load
  File "<frozen importlib._bootstrap>", line 955, in _find_and_load_unlocked
  File "<frozen importlib._bootstrap>", line 665, in _load_unlocked
  File "<frozen importlib._bootstrap_external>", line 678, in exec_module
  File "<frozen importlib._bootstrap>", line 219, in _call_with_frames_removed
  File "./XiaoChengxu/urls.py", line 18, in <module>
    from django.views.generic.base import RediectView
ImportError: cannot import name 'RediectView'

During handling of the above exception, another exception occurred:

Traceback (most recent call last):
  File "/usr/local/lib64/python3.6/site-packages/django/core/handlers/exception.py", line 34, in inner
    response = get_response(request)
  File "/usr/local/lib64/python3.6/site-packages/django/utils/deprecation.py", line 94, in __call__
    response = response or self.get_response(request)
  File "/usr/local/lib64/python3.6/site-packages/django/core/handlers/exception.py", line 36, in inner
    response = response_for_exception(request, exc)
  File "/usr/local/lib64/python3.6/site-packages/django/core/handlers/exception.py", line 90, in response_for_exception
    response = handle_uncaught_exception(request, get_resolver(get_urlconf()), sys.exc_info())
  File "/usr/local/lib64/python3.6/site-packages/django/core/handlers/exception.py", line 128, in handle_uncaught_exception
    callback, param_dict = resolver.resolve_error_handler(500)
  File "/usr/local/lib64/python3.6/site-packages/django/urls/resolvers.py", line 601, in resolve_error_handler
    callback = getattr(self.urlconf_module, 'handler%s' % view_type, None)
  File "/usr/local/lib64/python3.6/site-packages/django/utils/functional.py", line 48, in __get__
    res = instance.__dict__[self.name] = self.func(instance)
  File "/usr/local/lib64/python3.6/site-packages/django/urls/resolvers.py", line 581, in urlconf_module
    return import_module(self.urlconf_name)
  File "/usr/lib64/python3.6/importlib/__init__.py", line 126, in import_module
    return _bootstrap._gcd_import(name[level:], package, level)
  File "<frozen importlib._bootstrap>", line 994, in _gcd_import
  File "<frozen importlib._bootstrap>", line 971, in _find_and_load
  File "<frozen importlib._bootstrap>", line 955, in _find_and_load_unlocked
  File "<frozen importlib._bootstrap>", line 665, in _load_unlocked
  File "<frozen importlib._bootstrap_external>", line 678, in exec_module
  File "<frozen importlib._bootstrap>", line 219, in _call_with_frames_removed
  File "./XiaoChengxu/urls.py", line 18, in <module>
    from django.views.generic.base import RediectView
ImportError: cannot import name 'RediectView'

During handling of the above exception, another exception occurred:

Traceback (most recent call last):
  File "/usr/local/lib64/python3.6/site-packages/django/core/handlers/wsgi.py", line 133, in __call__
    response = self.get_response(request)
  File "/usr/local/lib64/python3.6/site-packages/django/core/handlers/base.py", line 75, in get_response
    response = self._middleware_chain(request)
  File "/usr/local/lib64/python3.6/site-packages/django/core/handlers/exception.py", line 36, in inner
    response = response_for_exception(request, exc)
  File "/usr/local/lib64/python3.6/site-packages/django/core/handlers/exception.py", line 90, in response_for_exception
    response = handle_uncaught_exception(request, get_resolver(get_urlconf()), sys.exc_info())
  File "/usr/local/lib64/python3.6/site-packages/django/core/handlers/exception.py", line 128, in handle_uncaught_exception
    callback, param_dict = resolver.resolve_error_handler(500)
  File "/usr/local/lib64/python3.6/site-packages/django/urls/resolvers.py", line 601, in resolve_error_handler
    callback = getattr(self.urlconf_module, 'handler%s' % view_type, None)
  File "/usr/local/lib64/python3.6/site-packages/django/utils/functional.py", line 48, in __get__
    res = instance.__dict__[self.name] = self.func(instance)
  File "/usr/local/lib64/python3.6/site-packages/django/urls/resolvers.py", line 581, in urlconf_module
    return import_module(self.urlconf_name)
  File "/usr/lib64/python3.6/importlib/__init__.py", line 126, in import_module
    return _bootstrap._gcd_import(name[level:], package, level)
  File "<frozen importlib._bootstrap>", line 994, in _gcd_import
  File "<frozen importlib._bootstrap>", line 971, in _find_and_load
  File "<frozen importlib._bootstrap>", line 955, in _find_and_load_unlocked
  File "<frozen importlib._bootstrap>", line 665, in _load_unlocked
  File "<frozen importlib._bootstrap_external>", line 678, in exec_module
  File "<frozen importlib._bootstrap>", line 219, in _call_with_frames_removed
  File "./XiaoChengxu/urls.py", line 18, in <module>
    from django.views.generic.base import RediectView
ImportError: cannot import name 'RediectView'
[pid: 61125|app: 0|req: 1/1] 103.244.59.2 () {52 vars in 1014 bytes} [Mon Aug 10 10:34:56 2020] GET /gly/ => generated 0 bytes in 20 msecs (HTTP/2.0 500) 0 headers in 0 bytes (0 switches on core 0)
[pid: 61126|app: 0|req: 1/2] 103.244.59.2 () {52 vars in 1014 bytes} [Mon Aug 10 10:36:33 2020] GET /gly/ => generated 3682 bytes in 207 msecs (HTTP/2.0 200) 7 headers in 263 bytes (1 switches on core 0)
[pid: 61127|app: 0|req: 1/3] 103.244.59.2 () {52 vars in 1081 bytes} [Mon Aug 10 10:36:37 2020] GET /gly/MRYW/daily_question/ => generated 7383 bytes in 246 msecs (HTTP/2.0 200) 8 headers in 431 bytes (1 switches on core 0)
[pid: 61124|app: 0|req: 1/4] 103.244.59.2 () {48 vars in 891 bytes} [Mon Aug 10 10:36:37 2020] GET /gly/jsi18n/ => generated 7722 bytes in 172 msecs (HTTP/2.0 200) 5 headers in 159 bytes (1 switches on core 0)
[pid: 61125|app: 0|req: 2/5] 103.244.59.2 () {52 vars in 1119 bytes} [Mon Aug 10 10:36:40 2020] GET /gly/MRYW/daily_question/9/change/ => generated 5847 bytes in 234 msecs (HTTP/2.0 200) 8 headers in 431 bytes (1 switches on core 0)
[pid: 61126|app: 0|req: 2/6] 103.244.59.2 () {48 vars in 900 bytes} [Mon Aug 10 10:36:41 2020] GET /gly/jsi18n/ => generated 7722 bytes in 7 msecs (HTTP/2.0 200) 5 headers in 159 bytes (1 switches on core 0)
[pid: 61127|app: 0|req: 2/7] 103.244.59.2 () {52 vars in 1110 bytes} [Mon Aug 10 10:36:46 2020] GET /gly/MRYW/daily_question/ => generated 7383 bytes in 23 msecs (HTTP/2.0 200) 8 headers in 431 bytes (1 switches on core 0)
[pid: 61124|app: 0|req: 2/8] 103.244.59.2 () {48 vars in 891 bytes} [Mon Aug 10 10:36:46 2020] GET /gly/jsi18n/ => generated 7722 bytes in 6 msecs (HTTP/2.0 200) 5 headers in 159 bytes (1 switches on core 0)
[pid: 61125|app: 0|req: 3/9] 103.244.59.2 () {52 vars in 1121 bytes} [Mon Aug 10 10:36:48 2020] GET /gly/MRYW/daily_question/10/change/ => generated 5794 bytes in 17 msecs (HTTP/2.0 200) 8 headers in 431 bytes (1 switches on core 0)
[pid: 61126|app: 0|req: 3/10] 103.244.59.2 () {48 vars in 901 bytes} [Mon Aug 10 10:36:48 2020] GET /gly/jsi18n/ => generated 7722 bytes in 6 msecs (HTTP/2.0 200) 5 headers in 159 bytes (1 switches on core 0)
[pid: 61127|app: 0|req: 3/11] 103.244.59.2 () {52 vars in 1111 bytes} [Mon Aug 10 10:36:53 2020] GET /gly/MRYW/daily_question/ => generated 7383 bytes in 24 msecs (HTTP/2.0 200) 8 headers in 431 bytes (1 switches on core 0)
[pid: 61124|app: 0|req: 3/12] 103.244.59.2 () {48 vars in 891 bytes} [Mon Aug 10 10:36:53 2020] GET /gly/jsi18n/ => generated 7722 bytes in 9 msecs (HTTP/2.0 200) 5 headers in 159 bytes (1 switches on core 0)
[pid: 61125|app: 0|req: 4/13] 103.244.59.2 () {52 vars in 1121 bytes} [Mon Aug 10 10:36:54 2020] GET /gly/MRYW/daily_question/11/change/ => generated 5782 bytes in 16 msecs (HTTP/2.0 200) 8 headers in 431 bytes (1 switches on core 0)
[pid: 61126|app: 0|req: 4/14] 103.244.59.2 () {48 vars in 901 bytes} [Mon Aug 10 10:36:54 2020] GET /gly/jsi18n/ => generated 7722 bytes in 7 msecs (HTTP/2.0 200) 5 headers in 159 bytes (1 switches on core 0)
[pid: 61127|app: 0|req: 4/15] 103.244.59.2 () {52 vars in 1111 bytes} [Mon Aug 10 10:36:57 2020] GET /gly/MRYW/daily_question/ => generated 7383 bytes in 23 msecs (HTTP/2.0 200) 8 headers in 431 bytes (1 switches on core 0)
[pid: 61124|app: 0|req: 4/16] 103.244.59.2 () {48 vars in 891 bytes} [Mon Aug 10 10:36:57 2020] GET /gly/jsi18n/ => generated 7722 bytes in 6 msecs (HTTP/2.0 200) 5 headers in 159 bytes (1 switches on core 0)
[pid: 61125|app: 0|req: 5/17] 103.244.59.2 () {52 vars in 1121 bytes} [Mon Aug 10 10:36:58 2020] GET /gly/MRYW/daily_question/12/change/ => generated 5893 bytes in 18 msecs (HTTP/2.0 200) 8 headers in 431 bytes (1 switches on core 0)
[pid: 61126|app: 0|req: 5/18] 103.244.59.2 () {48 vars in 901 bytes} [Mon Aug 10 10:36:58 2020] GET /gly/jsi18n/ => generated 7722 bytes in 6 msecs (HTTP/2.0 200) 5 headers in 159 bytes (1 switches on core 0)
[pid: 61127|app: 0|req: 5/19] 103.244.59.2 () {52 vars in 1111 bytes} [Mon Aug 10 10:37:00 2020] GET /gly/MRYW/daily_question/ => generated 7383 bytes in 22 msecs (HTTP/2.0 200) 8 headers in 431 bytes (1 switches on core 0)
[pid: 61124|app: 0|req: 5/20] 103.244.59.2 () {48 vars in 891 bytes} [Mon Aug 10 10:37:00 2020] GET /gly/jsi18n/ => generated 7722 bytes in 6 msecs (HTTP/2.0 200) 5 headers in 159 bytes (1 switches on core 0)
[pid: 61125|app: 0|req: 6/21] 103.244.59.2 () {52 vars in 1121 bytes} [Mon Aug 10 10:37:06 2020] GET /gly/MRYW/daily_question/13/change/ => generated 5670 bytes in 17 msecs (HTTP/2.0 200) 8 headers in 431 bytes (1 switches on core 0)
[pid: 61126|app: 0|req: 6/22] 103.244.59.2 () {48 vars in 901 bytes} [Mon Aug 10 10:37:06 2020] GET /gly/jsi18n/ => generated 7722 bytes in 6 msecs (HTTP/2.0 200) 5 headers in 159 bytes (1 switches on core 0)
[pid: 61127|app: 0|req: 6/23] 103.244.59.2 () {52 vars in 1131 bytes} [Mon Aug 10 10:37:12 2020] GET /gly/MRYW/daily_question/13/delete/ => generated 3242 bytes in 15 msecs (HTTP/2.0 200) 8 headers in 431 bytes (1 switches on core 0)
[pid: 61124|app: 0|req: 6/24] 103.244.59.2 () {60 vars in 1322 bytes} [Mon Aug 10 10:37:15 2020] POST /gly/MRYW/daily_question/13/delete/ => generated 0 bytes in 30 msecs (HTTP/2.0 302) 9 headers in 509 bytes (1 switches on core 0)
[pid: 61125|app: 0|req: 7/25] 103.244.59.2 () {54 vars in 1306 bytes} [Mon Aug 10 10:37:15 2020] GET /gly/MRYW/daily_question/ => generated 7307 bytes in 35 msecs (HTTP/2.0 200) 9 headers in 515 bytes (1 switches on core 0)
[pid: 61126|app: 0|req: 7/26] 103.244.59.2 () {48 vars in 891 bytes} [Mon Aug 10 10:37:16 2020] GET /gly/jsi18n/ => generated 7722 bytes in 6 msecs (HTTP/2.0 200) 5 headers in 159 bytes (1 switches on core 0)
[pid: 61127|app: 0|req: 7/27] 103.244.59.2 () {52 vars in 1121 bytes} [Mon Aug 10 10:37:18 2020] GET /gly/MRYW/daily_question/14/change/ => generated 5777 bytes in 27 msecs (HTTP/2.0 200) 8 headers in 431 bytes (1 switches on core 0)
[pid: 61124|app: 0|req: 7/28] 103.244.59.2 () {48 vars in 901 bytes} [Mon Aug 10 10:37:18 2020] GET /gly/jsi18n/ => generated 7722 bytes in 7 msecs (HTTP/2.0 200) 5 headers in 159 bytes (1 switches on core 0)
[pid: 61125|app: 0|req: 8/29] 103.244.59.2 () {52 vars in 1111 bytes} [Mon Aug 10 10:37:23 2020] GET /gly/MRYW/daily_question/ => generated 7154 bytes in 24 msecs (HTTP/2.0 200) 8 headers in 431 bytes (1 switches on core 0)
[pid: 61126|app: 0|req: 8/30] 103.244.59.2 () {48 vars in 891 bytes} [Mon Aug 10 10:37:23 2020] GET /gly/jsi18n/ => generated 7722 bytes in 7 msecs (HTTP/2.0 200) 5 headers in 159 bytes (1 switches on core 0)
[pid: 61127|app: 0|req: 8/31] 103.244.59.2 () {54 vars in 1142 bytes} [Mon Aug 10 10:42:41 2020] GET /gly/MRYW/daily_question/ => generated 7154 bytes in 32 msecs (HTTP/2.0 200) 8 headers in 431 bytes (1 switches on core 0)
[pid: 61124|app: 0|req: 8/32] 103.244.59.2 () {48 vars in 891 bytes} [Mon Aug 10 10:42:42 2020] GET /gly/jsi18n/ => generated 7722 bytes in 8 msecs (HTTP/2.0 200) 5 headers in 159 bytes (1 switches on core 0)
[pid: 61125|app: 0|req: 9/33] 89.248.174.166 () {30 vars in 333 bytes} [Mon Aug 10 11:31:30 2020] GET / => generated 179 bytes in 1 msecs (HTTP/1.1 404) 4 headers in 128 bytes (1 switches on core 0)
[pid: 61126|app: 0|req: 9/34] 47.100.7.135 () {36 vars in 457 bytes} [Mon Aug 10 12:15:01 2020] GET / => generated 179 bytes in 1 msecs (HTTP/1.1 404) 4 headers in 128 bytes (1 switches on core 0)
[pid: 61127|app: 0|req: 9/35] 47.101.38.110 () {30 vars in 371 bytes} [Mon Aug 10 12:45:02 2020] GET / => generated 179 bytes in 1 msecs (HTTP/1.1 404) 4 headers in 128 bytes (1 switches on core 0)
